Traceback (most recent call last):
  File "C:\Users\arnaou\AppData\Local\miniconda3\envs\dig4bio\Lib\site-packages\jupyter_cache\executors\utils.py", line 58, in single_nb_execution
    executenb(
  File "C:\Users\arnaou\AppData\Local\miniconda3\envs\dig4bio\Lib\site-packages\nbclient\client.py", line 1314, in execute
    return NotebookClient(nb=nb, resources=resources, km=km, **kwargs).execute()
           ^^^^^^^^^^^^^^^^^^^^^^^^^^^^^^^^^^^^^^^^^^^^^^^^^^^^^^^^^^^^^^^^^^^^^
  File "C:\Users\arnaou\AppData\Local\miniconda3\envs\dig4bio\Lib\site-packages\jupyter_core\utils\__init__.py", line 165, in wrapped
    return loop.run_until_complete(inner)
           ^^^^^^^^^^^^^^^^^^^^^^^^^^^^^^
  File "C:\Users\arnaou\AppData\Local\miniconda3\envs\dig4bio\Lib\asyncio\base_events.py", line 654, in run_until_complete
    return future.result()
           ^^^^^^^^^^^^^^^
  File "C:\Users\arnaou\AppData\Local\miniconda3\envs\dig4bio\Lib\site-packages\nbclient\client.py", line 709, in async_execute
    await self.async_execute_cell(
  File "C:\Users\arnaou\AppData\Local\miniconda3\envs\dig4bio\Lib\site-packages\nbclient\client.py", line 1062, in async_execute_cell
    await self._check_raise_for_error(cell, cell_index, exec_reply)
  File "C:\Users\arnaou\AppData\Local\miniconda3\envs\dig4bio\Lib\site-packages\nbclient\client.py", line 918, in _check_raise_for_error
    raise CellExecutionError.from_cell_and_msg(cell, exec_reply_content)
nbclient.exceptions.CellExecutionError: An error occurred while executing the following cell:
------------------
# Create pandas dataframe

# Your code here
df = pd.DataFrame()
df['Time'] = [0, 2, 4, 6, 8, 10, 12, 14, 16, 18, 20]
df['Cc'] = [0, 2.5, 3.13, 3.41, 3.57, 3.68, 3.75, 3.81, 3.85, 3.88, 3.91]
df['Ca'] = [c*2 for c in df['Cc']]
------------------


[1;31m---------------------------------------------------------------------------[0m
[1;31mNameError[0m                                 Traceback (most recent call last)
Cell [1;32mIn[3], line 4[0m
[0;32m      1[0m [38;5;66;03m# Create pandas dataframe[39;00m
[0;32m      2[0m 
[0;32m      3[0m [38;5;66;03m# Your code here[39;00m
[1;32m----> 4[0m df [38;5;241m=[39m [43mpd[49m[38;5;241m.[39mDataFrame()
[0;32m      5[0m df[[38;5;124m'[39m[38;5;124mTime[39m[38;5;124m'[39m] [38;5;241m=[39m [[38;5;241m0[39m, [38;5;241m2[39m, [38;5;241m4[39m, [38;5;241m6[39m, [38;5;241m8[39m, [38;5;241m10[39m, [38;5;241m12[39m, [38;5;241m14[39m, [38;5;241m16[39m, [38;5;241m18[39m, [38;5;241m20[39m]
[0;32m      6[0m df[[38;5;124m'[39m[38;5;124mCc[39m[38;5;124m'[39m] [38;5;241m=[39m [[38;5;241m0[39m, [38;5;241m2.5[39m, [38;5;241m3.13[39m, [38;5;241m3.41[39m, [38;5;241m3.57[39m, [38;5;241m3.68[39m, [38;5;241m3.75[39m, [38;5;241m3.81[39m, [38;5;241m3.85[39m, [38;5;241m3.88[39m, [38;5;241m3.91[39m]

[1;31mNameError[0m: name 'pd' is not defined

