Traceback (most recent call last):
  File "C:\Users\arnaou\AppData\Local\miniconda3\envs\dig4bio\Lib\site-packages\jupyter_cache\executors\utils.py", line 58, in single_nb_execution
    executenb(
  File "C:\Users\arnaou\AppData\Local\miniconda3\envs\dig4bio\Lib\site-packages\nbclient\client.py", line 1314, in execute
    return NotebookClient(nb=nb, resources=resources, km=km, **kwargs).execute()
           ^^^^^^^^^^^^^^^^^^^^^^^^^^^^^^^^^^^^^^^^^^^^^^^^^^^^^^^^^^^^^^^^^^^^^
  File "C:\Users\arnaou\AppData\Local\miniconda3\envs\dig4bio\Lib\site-packages\jupyter_core\utils\__init__.py", line 165, in wrapped
    return loop.run_until_complete(inner)
           ^^^^^^^^^^^^^^^^^^^^^^^^^^^^^^
  File "C:\Users\arnaou\AppData\Local\miniconda3\envs\dig4bio\Lib\asyncio\base_events.py", line 654, in run_until_complete
    return future.result()
           ^^^^^^^^^^^^^^^
  File "C:\Users\arnaou\AppData\Local\miniconda3\envs\dig4bio\Lib\site-packages\nbclient\client.py", line 709, in async_execute
    await self.async_execute_cell(
  File "C:\Users\arnaou\AppData\Local\miniconda3\envs\dig4bio\Lib\site-packages\nbclient\client.py", line 1062, in async_execute_cell
    await self._check_raise_for_error(cell, cell_index, exec_reply)
  File "C:\Users\arnaou\AppData\Local\miniconda3\envs\dig4bio\Lib\site-packages\nbclient\client.py", line 918, in _check_raise_for_error
    raise CellExecutionError.from_cell_and_msg(cell, exec_reply_content)
nbclient.exceptions.CellExecutionError: An error occurred while executing the following cell:
------------------
print(set_experiments[0])
------------------


[1;31m---------------------------------------------------------------------------[0m
[1;31mTypeError[0m                                 Traceback (most recent call last)
Cell [1;32mIn[8], line 1[0m
[1;32m----> 1[0m [38;5;28mprint[39m([43mset_experiments[49m[43m[[49m[38;5;241;43m0[39;49m[43m][49m)

[1;31mTypeError[0m: 'set' object is not subscriptable

